[2025-07-19T15:00:32.423+0000] {local_task_job_runner.py:120} INFO - ::group::Pre task execution logs
[2025-07-19T15:00:32.610+0000] {taskinstance.py:2076} INFO - Dependencies all met for dep_context=non-requeueable deps ti=<TaskInstance: ferry_portfolio_etl.dvc_add_data scheduled__2025-07-19T14:50:00+00:00 [queued]>
[2025-07-19T15:00:32.638+0000] {taskinstance.py:2076} INFO - Dependencies all met for dep_context=requeueable deps ti=<TaskInstance: ferry_portfolio_etl.dvc_add_data scheduled__2025-07-19T14:50:00+00:00 [queued]>
[2025-07-19T15:00:32.639+0000] {taskinstance.py:2306} INFO - Starting attempt 2 of 2
[2025-07-19T15:00:32.682+0000] {taskinstance.py:2330} INFO - Executing <Task(PythonOperator): dvc_add_data> on 2025-07-19 14:50:00+00:00
[2025-07-19T15:00:32.825+0000] {standard_task_runner.py:90} INFO - Running: ['***', 'tasks', 'run', 'ferry_portfolio_etl', 'dvc_add_data', 'scheduled__2025-07-19T14:50:00+00:00', '--job-id', '124', '--raw', '--subdir', 'DAGS_FOLDER/ferry_pipeline_dag.py', '--cfg-path', '/tmp/tmp1aocp1c8']
[2025-07-19T15:00:32.842+0000] {logging_mixin.py:188} WARNING - /home/***/.local/lib/python3.12/site-packages/***/task/task_runner/standard_task_runner.py:61 DeprecationWarning: This process (pid=1027) is multi-threaded, use of fork() may lead to deadlocks in the child.
[2025-07-19T15:00:32.862+0000] {standard_task_runner.py:91} INFO - Job 124: Subtask dvc_add_data
[2025-07-19T15:00:32.862+0000] {standard_task_runner.py:63} INFO - Started process 1029 to run task
[2025-07-19T15:00:33.066+0000] {logging_mixin.py:188} WARNING - /home/***/.local/lib/python3.12/site-packages/***/settings.py:195 DeprecationWarning: The sql_alchemy_conn option in [core] has been moved to the sql_alchemy_conn option in [database] - the old setting has been used, but please update your config.
[2025-07-19T15:00:33.305+0000] {task_command.py:426} INFO - Running <TaskInstance: ferry_portfolio_etl.dvc_add_data scheduled__2025-07-19T14:50:00+00:00 [running]> on host 0611430c3c10
[2025-07-19T15:00:33.791+0000] {taskinstance.py:2648} INFO - Exporting env vars: AIRFLOW_CTX_DAG_OWNER='ashok' AIRFLOW_CTX_DAG_ID='ferry_portfolio_etl' AIRFLOW_CTX_TASK_ID='dvc_add_data' AIRFLOW_CTX_EXECUTION_DATE='2025-07-19T14:50:00+00:00' AIRFLOW_CTX_TRY_NUMBER='2' AIRFLOW_CTX_DAG_RUN_ID='scheduled__2025-07-19T14:50:00+00:00'
[2025-07-19T15:00:33.842+0000] {taskinstance.py:430} INFO - ::endgroup::
[2025-07-19T15:00:33.922+0000] {logging_mixin.py:188} INFO - File exists? True artifacts/ferry_raw.csv
[2025-07-19T15:00:33.934+0000] {taskinstance.py:441} INFO - ::group::Post task execution logs
[2025-07-19T15:00:33.938+0000] {taskinstance.py:2905} ERROR - Task failed with exception
Traceback (most recent call last):
  File "/home/airflow/.local/lib/python3.12/site-packages/airflow/models/taskinstance.py", line 465, in _execute_task
    result = _execute_callable(context=context, **execute_callable_kwargs)
             ^^^^^^^^^^^^^^^^^^^^^^^^^^^^^^^^^^^^^^^^^^^^^^^^^^^^^^^^^^^^^
  File "/home/airflow/.local/lib/python3.12/site-packages/airflow/models/taskinstance.py", line 432, in _execute_callable
    return execute_callable(context=context, **execute_callable_kwargs)
           ^^^^^^^^^^^^^^^^^^^^^^^^^^^^^^^^^^^^^^^^^^^^^^^^^^^^^^^^^^^^
  File "/home/airflow/.local/lib/python3.12/site-packages/airflow/models/baseoperator.py", line 400, in wrapper
    return func(self, *args, **kwargs)
           ^^^^^^^^^^^^^^^^^^^^^^^^^^^
  File "/home/airflow/.local/lib/python3.12/site-packages/airflow/operators/python.py", line 235, in execute
    return_value = self.execute_callable()
                   ^^^^^^^^^^^^^^^^^^^^^^^
  File "/home/airflow/.local/lib/python3.12/site-packages/airflow/operators/python.py", line 252, in execute_callable
    return self.python_callable(*self.op_args, **self.op_kwargs)
           ^^^^^^^^^^^^^^^^^^^^^^^^^^^^^^^^^^^^^^^^^^^^^^^^^^^^^
  File "/opt/airflow/dags/ferry_pipeline_dag.py", line 21, in run_dvc_add
    subprocess.run(["dvc", "add", data_path], check=True)
  File "/usr/local/lib/python3.12/subprocess.py", line 548, in run
    with Popen(*popenargs, **kwargs) as process:
         ^^^^^^^^^^^^^^^^^^^^^^^^^^^
  File "/usr/local/lib/python3.12/subprocess.py", line 1026, in __init__
    self._execute_child(args, executable, preexec_fn, close_fds,
  File "/usr/local/lib/python3.12/subprocess.py", line 1955, in _execute_child
    raise child_exception_type(errno_num, err_msg, err_filename)
PermissionError: [Errno 13] Permission denied: 'dvc'
[2025-07-19T15:00:34.010+0000] {taskinstance.py:1206} INFO - Marking task as FAILED. dag_id=ferry_portfolio_etl, task_id=dvc_add_data, run_id=scheduled__2025-07-19T14:50:00+00:00, execution_date=20250719T145000, start_date=20250719T150032, end_date=20250719T150034
[2025-07-19T15:00:34.049+0000] {standard_task_runner.py:110} ERROR - Failed to execute job 124 for task dvc_add_data ([Errno 13] Permission denied: 'dvc'; 1029)
[2025-07-19T15:00:34.082+0000] {local_task_job_runner.py:240} INFO - Task exited with return code 1
[2025-07-19T15:00:34.128+0000] {taskinstance.py:3498} INFO - 0 downstream tasks scheduled from follow-on schedule check
[2025-07-19T15:00:34.137+0000] {local_task_job_runner.py:222} INFO - ::endgroup::
