[2025-07-19T16:20:24.681+0000] {local_task_job_runner.py:120} INFO - ::group::Pre task execution logs
[2025-07-19T16:20:24.719+0000] {taskinstance.py:2076} INFO - Dependencies all met for dep_context=non-requeueable deps ti=<TaskInstance: ferry_portfolio_etl.dvc_add_data scheduled__2025-07-19T16:10:00+00:00 [queued]>
[2025-07-19T16:20:24.729+0000] {taskinstance.py:2076} INFO - Dependencies all met for dep_context=requeueable deps ti=<TaskInstance: ferry_portfolio_etl.dvc_add_data scheduled__2025-07-19T16:10:00+00:00 [queued]>
[2025-07-19T16:20:24.730+0000] {taskinstance.py:2306} INFO - Starting attempt 2 of 2
[2025-07-19T16:20:24.745+0000] {taskinstance.py:2330} INFO - Executing <Task(PythonOperator): dvc_add_data> on 2025-07-19 16:10:00+00:00
[2025-07-19T16:20:24.759+0000] {logging_mixin.py:188} WARNING - /home/***/.local/lib/python3.12/site-packages/***/task/task_runner/standard_task_runner.py:61 DeprecationWarning: This process (pid=1797) is multi-threaded, use of fork() may lead to deadlocks in the child.
[2025-07-19T16:20:24.762+0000] {standard_task_runner.py:63} INFO - Started process 1799 to run task
[2025-07-19T16:20:24.760+0000] {standard_task_runner.py:90} INFO - Running: ['***', 'tasks', 'run', 'ferry_portfolio_etl', 'dvc_add_data', 'scheduled__2025-07-19T16:10:00+00:00', '--job-id', '173', '--raw', '--subdir', 'DAGS_FOLDER/ferry_pipeline_dag.py', '--cfg-path', '/tmp/tmphclywa6a']
[2025-07-19T16:20:24.764+0000] {standard_task_runner.py:91} INFO - Job 173: Subtask dvc_add_data
[2025-07-19T16:20:24.787+0000] {logging_mixin.py:188} WARNING - /home/***/.local/lib/python3.12/site-packages/***/settings.py:195 DeprecationWarning: The sql_alchemy_conn option in [core] has been moved to the sql_alchemy_conn option in [database] - the old setting has been used, but please update your config.
[2025-07-19T16:20:24.853+0000] {task_command.py:426} INFO - Running <TaskInstance: ferry_portfolio_etl.dvc_add_data scheduled__2025-07-19T16:10:00+00:00 [running]> on host 289e2533e87e
[2025-07-19T16:20:24.970+0000] {taskinstance.py:2648} INFO - Exporting env vars: AIRFLOW_CTX_DAG_OWNER='ashok' AIRFLOW_CTX_DAG_ID='ferry_portfolio_etl' AIRFLOW_CTX_TASK_ID='dvc_add_data' AIRFLOW_CTX_EXECUTION_DATE='2025-07-19T16:10:00+00:00' AIRFLOW_CTX_TRY_NUMBER='2' AIRFLOW_CTX_DAG_RUN_ID='scheduled__2025-07-19T16:10:00+00:00'
[2025-07-19T16:20:24.973+0000] {taskinstance.py:430} INFO - ::endgroup::
[2025-07-19T16:20:24.990+0000] {logging_mixin.py:188} INFO - File exists? True artifacts/ferry_raw.csv
[2025-07-19T16:20:26.335+0000] {taskinstance.py:441} INFO - ::group::Post task execution logs
[2025-07-19T16:20:26.336+0000] {taskinstance.py:2905} ERROR - Task failed with exception
Traceback (most recent call last):
  File "/home/airflow/.local/lib/python3.12/site-packages/airflow/models/taskinstance.py", line 465, in _execute_task
    result = _execute_callable(context=context, **execute_callable_kwargs)
             ^^^^^^^^^^^^^^^^^^^^^^^^^^^^^^^^^^^^^^^^^^^^^^^^^^^^^^^^^^^^^
  File "/home/airflow/.local/lib/python3.12/site-packages/airflow/models/taskinstance.py", line 432, in _execute_callable
    return execute_callable(context=context, **execute_callable_kwargs)
           ^^^^^^^^^^^^^^^^^^^^^^^^^^^^^^^^^^^^^^^^^^^^^^^^^^^^^^^^^^^^
  File "/home/airflow/.local/lib/python3.12/site-packages/airflow/models/baseoperator.py", line 400, in wrapper
    return func(self, *args, **kwargs)
           ^^^^^^^^^^^^^^^^^^^^^^^^^^^
  File "/home/airflow/.local/lib/python3.12/site-packages/airflow/operators/python.py", line 235, in execute
    return_value = self.execute_callable()
                   ^^^^^^^^^^^^^^^^^^^^^^^
  File "/home/airflow/.local/lib/python3.12/site-packages/airflow/operators/python.py", line 252, in execute_callable
    return self.python_callable(*self.op_args, **self.op_kwargs)
           ^^^^^^^^^^^^^^^^^^^^^^^^^^^^^^^^^^^^^^^^^^^^^^^^^^^^^
  File "/opt/airflow/dags/ferry_pipeline_dag.py", line 51, in run_dvc_add
    subprocess.run(["dvc", "add", data_path], check=True)
  File "/usr/local/lib/python3.12/subprocess.py", line 571, in run
    raise CalledProcessError(retcode, process.args,
subprocess.CalledProcessError: Command '['dvc', 'add', 'artifacts/ferry_raw.csv']' returned non-zero exit status 253.
[2025-07-19T16:20:26.353+0000] {taskinstance.py:1206} INFO - Marking task as FAILED. dag_id=ferry_portfolio_etl, task_id=dvc_add_data, run_id=scheduled__2025-07-19T16:10:00+00:00, execution_date=20250719T161000, start_date=20250719T162024, end_date=20250719T162026
[2025-07-19T16:20:26.369+0000] {standard_task_runner.py:110} ERROR - Failed to execute job 173 for task dvc_add_data (Command '['dvc', 'add', 'artifacts/ferry_raw.csv']' returned non-zero exit status 253.; 1799)
[2025-07-19T16:20:26.425+0000] {local_task_job_runner.py:240} INFO - Task exited with return code 1
[2025-07-19T16:20:26.456+0000] {taskinstance.py:3498} INFO - 0 downstream tasks scheduled from follow-on schedule check
[2025-07-19T16:20:26.462+0000] {local_task_job_runner.py:222} INFO - ::endgroup::
