[2025-07-19T16:00:26.239+0000] {local_task_job_runner.py:120} INFO - ::group::Pre task execution logs
[2025-07-19T16:00:26.275+0000] {taskinstance.py:2076} INFO - Dependencies all met for dep_context=non-requeueable deps ti=<TaskInstance: ferry_portfolio_etl.dvc_add_data scheduled__2025-07-19T15:50:00+00:00 [queued]>
[2025-07-19T16:00:26.284+0000] {taskinstance.py:2076} INFO - Dependencies all met for dep_context=requeueable deps ti=<TaskInstance: ferry_portfolio_etl.dvc_add_data scheduled__2025-07-19T15:50:00+00:00 [queued]>
[2025-07-19T16:00:26.285+0000] {taskinstance.py:2306} INFO - Starting attempt 2 of 2
[2025-07-19T16:00:26.301+0000] {taskinstance.py:2330} INFO - Executing <Task(PythonOperator): dvc_add_data> on 2025-07-19 15:50:00+00:00
[2025-07-19T16:00:26.316+0000] {logging_mixin.py:188} WARNING - /home/***/.local/lib/python3.12/site-packages/***/task/task_runner/standard_task_runner.py:61 DeprecationWarning: This process (pid=1373) is multi-threaded, use of fork() may lead to deadlocks in the child.
[2025-07-19T16:00:26.318+0000] {standard_task_runner.py:63} INFO - Started process 1375 to run task
[2025-07-19T16:00:26.316+0000] {standard_task_runner.py:90} INFO - Running: ['***', 'tasks', 'run', 'ferry_portfolio_etl', 'dvc_add_data', 'scheduled__2025-07-19T15:50:00+00:00', '--job-id', '161', '--raw', '--subdir', 'DAGS_FOLDER/ferry_pipeline_dag.py', '--cfg-path', '/tmp/tmp8wk9t4h0']
[2025-07-19T16:00:26.319+0000] {standard_task_runner.py:91} INFO - Job 161: Subtask dvc_add_data
[2025-07-19T16:00:26.343+0000] {logging_mixin.py:188} WARNING - /home/***/.local/lib/python3.12/site-packages/***/settings.py:195 DeprecationWarning: The sql_alchemy_conn option in [core] has been moved to the sql_alchemy_conn option in [database] - the old setting has been used, but please update your config.
[2025-07-19T16:00:26.409+0000] {task_command.py:426} INFO - Running <TaskInstance: ferry_portfolio_etl.dvc_add_data scheduled__2025-07-19T15:50:00+00:00 [running]> on host 289e2533e87e
[2025-07-19T16:00:26.528+0000] {taskinstance.py:2648} INFO - Exporting env vars: AIRFLOW_CTX_DAG_OWNER='ashok' AIRFLOW_CTX_DAG_ID='ferry_portfolio_etl' AIRFLOW_CTX_TASK_ID='dvc_add_data' AIRFLOW_CTX_EXECUTION_DATE='2025-07-19T15:50:00+00:00' AIRFLOW_CTX_TRY_NUMBER='2' AIRFLOW_CTX_DAG_RUN_ID='scheduled__2025-07-19T15:50:00+00:00'
[2025-07-19T16:00:26.529+0000] {taskinstance.py:430} INFO - ::endgroup::
[2025-07-19T16:00:26.545+0000] {logging_mixin.py:188} INFO - File exists? True artifacts/ferry_raw.csv
[2025-07-19T16:00:27.892+0000] {taskinstance.py:441} INFO - ::group::Post task execution logs
[2025-07-19T16:00:27.893+0000] {taskinstance.py:2905} ERROR - Task failed with exception
Traceback (most recent call last):
  File "/home/airflow/.local/lib/python3.12/site-packages/airflow/models/taskinstance.py", line 465, in _execute_task
    result = _execute_callable(context=context, **execute_callable_kwargs)
             ^^^^^^^^^^^^^^^^^^^^^^^^^^^^^^^^^^^^^^^^^^^^^^^^^^^^^^^^^^^^^
  File "/home/airflow/.local/lib/python3.12/site-packages/airflow/models/taskinstance.py", line 432, in _execute_callable
    return execute_callable(context=context, **execute_callable_kwargs)
           ^^^^^^^^^^^^^^^^^^^^^^^^^^^^^^^^^^^^^^^^^^^^^^^^^^^^^^^^^^^^
  File "/home/airflow/.local/lib/python3.12/site-packages/airflow/models/baseoperator.py", line 400, in wrapper
    return func(self, *args, **kwargs)
           ^^^^^^^^^^^^^^^^^^^^^^^^^^^
  File "/home/airflow/.local/lib/python3.12/site-packages/airflow/operators/python.py", line 235, in execute
    return_value = self.execute_callable()
                   ^^^^^^^^^^^^^^^^^^^^^^^
  File "/home/airflow/.local/lib/python3.12/site-packages/airflow/operators/python.py", line 252, in execute_callable
    return self.python_callable(*self.op_args, **self.op_kwargs)
           ^^^^^^^^^^^^^^^^^^^^^^^^^^^^^^^^^^^^^^^^^^^^^^^^^^^^^
  File "/opt/airflow/dags/ferry_pipeline_dag.py", line 51, in run_dvc_add
    subprocess.run(["dvc", "add", data_path], check=True)
  File "/usr/local/lib/python3.12/subprocess.py", line 571, in run
    raise CalledProcessError(retcode, process.args,
subprocess.CalledProcessError: Command '['dvc', 'add', 'artifacts/ferry_raw.csv']' returned non-zero exit status 253.
[2025-07-19T16:00:27.913+0000] {taskinstance.py:1206} INFO - Marking task as FAILED. dag_id=ferry_portfolio_etl, task_id=dvc_add_data, run_id=scheduled__2025-07-19T15:50:00+00:00, execution_date=20250719T155000, start_date=20250719T160026, end_date=20250719T160027
[2025-07-19T16:00:27.929+0000] {standard_task_runner.py:110} ERROR - Failed to execute job 161 for task dvc_add_data (Command '['dvc', 'add', 'artifacts/ferry_raw.csv']' returned non-zero exit status 253.; 1375)
[2025-07-19T16:00:27.982+0000] {local_task_job_runner.py:240} INFO - Task exited with return code 1
[2025-07-19T16:00:27.998+0000] {local_task_job_runner.py:222} INFO - ::endgroup::
