[2025-07-19T02:59:55.783+0000] {local_task_job_runner.py:120} INFO - ::group::Pre task execution logs
[2025-07-19T02:59:55.847+0000] {taskinstance.py:2076} INFO - Dependencies all met for dep_context=non-requeueable deps ti=<TaskInstance: ferry_portfolio_etl.dvc_add_data manual__2025-07-19T02:51:57.176179+00:00 [queued]>
[2025-07-19T02:59:55.864+0000] {taskinstance.py:2076} INFO - Dependencies all met for dep_context=requeueable deps ti=<TaskInstance: ferry_portfolio_etl.dvc_add_data manual__2025-07-19T02:51:57.176179+00:00 [queued]>
[2025-07-19T02:59:55.865+0000] {taskinstance.py:2306} INFO - Starting attempt 2 of 2
[2025-07-19T02:59:55.887+0000] {taskinstance.py:2330} INFO - Executing <Task(PythonOperator): dvc_add_data> on 2025-07-19 02:51:57.176179+00:00
[2025-07-19T02:59:55.995+0000] {logging_mixin.py:188} WARNING - /home/***/.local/lib/python3.12/site-packages/***/task/task_runner/standard_task_runner.py:61 DeprecationWarning: This process (pid=172) is multi-threaded, use of fork() may lead to deadlocks in the child.
[2025-07-19T02:59:55.998+0000] {standard_task_runner.py:63} INFO - Started process 178 to run task
[2025-07-19T02:59:55.996+0000] {standard_task_runner.py:90} INFO - Running: ['***', 'tasks', 'run', 'ferry_portfolio_etl', 'dvc_add_data', 'manual__2025-07-19T02:51:57.176179+00:00', '--job-id', '9', '--raw', '--subdir', 'DAGS_FOLDER/ferry_pipeline_dag.py', '--cfg-path', '/tmp/tmpf60omao9']
[2025-07-19T02:59:56.000+0000] {standard_task_runner.py:91} INFO - Job 9: Subtask dvc_add_data
[2025-07-19T02:59:56.043+0000] {logging_mixin.py:188} WARNING - /home/***/.local/lib/python3.12/site-packages/***/settings.py:195 DeprecationWarning: The sql_alchemy_conn option in [core] has been moved to the sql_alchemy_conn option in [database] - the old setting has been used, but please update your config.
[2025-07-19T02:59:56.126+0000] {task_command.py:426} INFO - Running <TaskInstance: ferry_portfolio_etl.dvc_add_data manual__2025-07-19T02:51:57.176179+00:00 [running]> on host 4a4916efbe02
[2025-07-19T02:59:56.306+0000] {taskinstance.py:2648} INFO - Exporting env vars: AIRFLOW_CTX_DAG_OWNER='ashok' AIRFLOW_CTX_DAG_ID='ferry_portfolio_etl' AIRFLOW_CTX_TASK_ID='dvc_add_data' AIRFLOW_CTX_EXECUTION_DATE='2025-07-19T02:51:57.176179+00:00' AIRFLOW_CTX_TRY_NUMBER='2' AIRFLOW_CTX_DAG_RUN_ID='manual__2025-07-19T02:51:57.176179+00:00'
[2025-07-19T02:59:56.314+0000] {taskinstance.py:430} INFO - ::endgroup::
[2025-07-19T03:00:00.072+0000] {taskinstance.py:441} INFO - ::group::Post task execution logs
[2025-07-19T03:00:00.075+0000] {taskinstance.py:2905} ERROR - Task failed with exception
Traceback (most recent call last):
  File "/home/airflow/.local/lib/python3.12/site-packages/airflow/models/taskinstance.py", line 465, in _execute_task
    result = _execute_callable(context=context, **execute_callable_kwargs)
             ^^^^^^^^^^^^^^^^^^^^^^^^^^^^^^^^^^^^^^^^^^^^^^^^^^^^^^^^^^^^^
  File "/home/airflow/.local/lib/python3.12/site-packages/airflow/models/taskinstance.py", line 432, in _execute_callable
    return execute_callable(context=context, **execute_callable_kwargs)
           ^^^^^^^^^^^^^^^^^^^^^^^^^^^^^^^^^^^^^^^^^^^^^^^^^^^^^^^^^^^^
  File "/home/airflow/.local/lib/python3.12/site-packages/airflow/models/baseoperator.py", line 400, in wrapper
    return func(self, *args, **kwargs)
           ^^^^^^^^^^^^^^^^^^^^^^^^^^^
  File "/home/airflow/.local/lib/python3.12/site-packages/airflow/operators/python.py", line 235, in execute
    return_value = self.execute_callable()
                   ^^^^^^^^^^^^^^^^^^^^^^^
  File "/home/airflow/.local/lib/python3.12/site-packages/airflow/operators/python.py", line 252, in execute_callable
    return self.python_callable(*self.op_args, **self.op_kwargs)
           ^^^^^^^^^^^^^^^^^^^^^^^^^^^^^^^^^^^^^^^^^^^^^^^^^^^^^
  File "/opt/airflow/dags/ferry_pipeline_dag.py", line 12, in run_dvc_add
    subprocess.run(["dvc", "add", data_path], check=True)
  File "/usr/local/lib/python3.12/subprocess.py", line 571, in run
    raise CalledProcessError(retcode, process.args,
subprocess.CalledProcessError: Command '['dvc', 'add', 'artifacts/ferry_raw.csv']' returned non-zero exit status 255.
[2025-07-19T03:00:00.104+0000] {taskinstance.py:1206} INFO - Marking task as FAILED. dag_id=ferry_portfolio_etl, task_id=dvc_add_data, run_id=manual__2025-07-19T02:51:57.176179+00:00, execution_date=20250719T025157, start_date=20250719T025955, end_date=20250719T030000
[2025-07-19T03:00:00.131+0000] {standard_task_runner.py:110} ERROR - Failed to execute job 9 for task dvc_add_data (Command '['dvc', 'add', 'artifacts/ferry_raw.csv']' returned non-zero exit status 255.; 178)
[2025-07-19T03:00:00.188+0000] {local_task_job_runner.py:240} INFO - Task exited with return code 1
[2025-07-19T03:00:00.227+0000] {taskinstance.py:3498} INFO - 0 downstream tasks scheduled from follow-on schedule check
[2025-07-19T03:00:00.239+0000] {local_task_job_runner.py:222} INFO - ::endgroup::
