[2025-07-19T17:15:26.829+0000] {local_task_job_runner.py:120} INFO - ::group::Pre task execution logs
[2025-07-19T17:15:26.944+0000] {taskinstance.py:2076} INFO - Dependencies all met for dep_context=non-requeueable deps ti=<TaskInstance: ferry_portfolio_etl.dvc_add_data scheduled__2025-07-19T17:05:00+00:00 [queued]>
[2025-07-19T17:15:26.959+0000] {taskinstance.py:2076} INFO - Dependencies all met for dep_context=requeueable deps ti=<TaskInstance: ferry_portfolio_etl.dvc_add_data scheduled__2025-07-19T17:05:00+00:00 [queued]>
[2025-07-19T17:15:26.960+0000] {taskinstance.py:2306} INFO - Starting attempt 2 of 2
[2025-07-19T17:15:26.987+0000] {taskinstance.py:2330} INFO - Executing <Task(PythonOperator): dvc_add_data> on 2025-07-19 17:05:00+00:00
[2025-07-19T17:15:27.027+0000] {logging_mixin.py:188} WARNING - /home/***/.local/lib/python3.12/site-packages/***/task/task_runner/standard_task_runner.py:61 DeprecationWarning: This process (pid=590) is multi-threaded, use of fork() may lead to deadlocks in the child.
[2025-07-19T17:15:27.036+0000] {standard_task_runner.py:63} INFO - Started process 592 to run task
[2025-07-19T17:15:27.031+0000] {standard_task_runner.py:90} INFO - Running: ['***', 'tasks', 'run', 'ferry_portfolio_etl', 'dvc_add_data', 'scheduled__2025-07-19T17:05:00+00:00', '--job-id', '212', '--raw', '--subdir', 'DAGS_FOLDER/ferry_pipeline_dag.py', '--cfg-path', '/tmp/tmpsn9e2dhy']
[2025-07-19T17:15:27.047+0000] {standard_task_runner.py:91} INFO - Job 212: Subtask dvc_add_data
[2025-07-19T17:15:27.103+0000] {logging_mixin.py:188} WARNING - /home/***/.local/lib/python3.12/site-packages/***/settings.py:195 DeprecationWarning: The sql_alchemy_conn option in [core] has been moved to the sql_alchemy_conn option in [database] - the old setting has been used, but please update your config.
[2025-07-19T17:15:27.426+0000] {task_command.py:426} INFO - Running <TaskInstance: ferry_portfolio_etl.dvc_add_data scheduled__2025-07-19T17:05:00+00:00 [running]> on host ee9d4808f134
[2025-07-19T17:15:27.770+0000] {taskinstance.py:2648} INFO - Exporting env vars: AIRFLOW_CTX_DAG_OWNER='ashok' AIRFLOW_CTX_DAG_ID='ferry_portfolio_etl' AIRFLOW_CTX_TASK_ID='dvc_add_data' AIRFLOW_CTX_EXECUTION_DATE='2025-07-19T17:05:00+00:00' AIRFLOW_CTX_TRY_NUMBER='2' AIRFLOW_CTX_DAG_RUN_ID='scheduled__2025-07-19T17:05:00+00:00'
[2025-07-19T17:15:27.779+0000] {taskinstance.py:430} INFO - ::endgroup::
[2025-07-19T17:15:27.862+0000] {logging_mixin.py:188} INFO - File exists? True /opt/***/artifacts/ferry_raw.csv
[2025-07-19T17:15:30.429+0000] {taskinstance.py:441} INFO - ::group::Post task execution logs
[2025-07-19T17:15:30.430+0000] {taskinstance.py:2905} ERROR - Task failed with exception
Traceback (most recent call last):
  File "/home/airflow/.local/lib/python3.12/site-packages/airflow/models/taskinstance.py", line 465, in _execute_task
    result = _execute_callable(context=context, **execute_callable_kwargs)
             ^^^^^^^^^^^^^^^^^^^^^^^^^^^^^^^^^^^^^^^^^^^^^^^^^^^^^^^^^^^^^
  File "/home/airflow/.local/lib/python3.12/site-packages/airflow/models/taskinstance.py", line 432, in _execute_callable
    return execute_callable(context=context, **execute_callable_kwargs)
           ^^^^^^^^^^^^^^^^^^^^^^^^^^^^^^^^^^^^^^^^^^^^^^^^^^^^^^^^^^^^
  File "/home/airflow/.local/lib/python3.12/site-packages/airflow/models/baseoperator.py", line 400, in wrapper
    return func(self, *args, **kwargs)
           ^^^^^^^^^^^^^^^^^^^^^^^^^^^
  File "/home/airflow/.local/lib/python3.12/site-packages/airflow/operators/python.py", line 235, in execute
    return_value = self.execute_callable()
                   ^^^^^^^^^^^^^^^^^^^^^^^
  File "/home/airflow/.local/lib/python3.12/site-packages/airflow/operators/python.py", line 252, in execute_callable
    return self.python_callable(*self.op_args, **self.op_kwargs)
           ^^^^^^^^^^^^^^^^^^^^^^^^^^^^^^^^^^^^^^^^^^^^^^^^^^^^^
  File "/opt/airflow/dags/ferry_pipeline_dag.py", line 51, in run_dvc_add
    subprocess.run(["dvc", "add", data_path], check=True)
  File "/usr/local/lib/python3.12/subprocess.py", line 571, in run
    raise CalledProcessError(retcode, process.args,
subprocess.CalledProcessError: Command '['dvc', 'add', '/opt/airflow/artifacts/ferry_raw.csv']' returned non-zero exit status 253.
[2025-07-19T17:15:30.491+0000] {taskinstance.py:1206} INFO - Marking task as FAILED. dag_id=ferry_portfolio_etl, task_id=dvc_add_data, run_id=scheduled__2025-07-19T17:05:00+00:00, execution_date=20250719T170500, start_date=20250719T171526, end_date=20250719T171530
[2025-07-19T17:15:30.515+0000] {standard_task_runner.py:110} ERROR - Failed to execute job 212 for task dvc_add_data (Command '['dvc', 'add', '/opt/airflow/artifacts/ferry_raw.csv']' returned non-zero exit status 253.; 592)
[2025-07-19T17:15:30.552+0000] {local_task_job_runner.py:240} INFO - Task exited with return code 1
[2025-07-19T17:15:30.588+0000] {taskinstance.py:3498} INFO - 0 downstream tasks scheduled from follow-on schedule check
[2025-07-19T17:15:30.595+0000] {local_task_job_runner.py:222} INFO - ::endgroup::
