[2025-07-18T20:25:13.331+0000] {local_task_job_runner.py:120} INFO - ::group::Pre task execution logs
[2025-07-18T20:25:13.370+0000] {taskinstance.py:2076} INFO - Dependencies all met for dep_context=non-requeueable deps ti=<TaskInstance: ferry_portfolio_etl.transform_data scheduled__2025-07-18T20:20:00+00:00 [queued]>
[2025-07-18T20:25:13.380+0000] {taskinstance.py:2076} INFO - Dependencies all met for dep_context=requeueable deps ti=<TaskInstance: ferry_portfolio_etl.transform_data scheduled__2025-07-18T20:20:00+00:00 [queued]>
[2025-07-18T20:25:13.381+0000] {taskinstance.py:2306} INFO - Starting attempt 1 of 2
[2025-07-18T20:25:13.395+0000] {taskinstance.py:2330} INFO - Executing <Task(PythonOperator): transform_data> on 2025-07-18 20:20:00+00:00
[2025-07-18T20:25:13.422+0000] {standard_task_runner.py:90} INFO - Running: ['***', 'tasks', 'run', 'ferry_portfolio_etl', 'transform_data', 'scheduled__2025-07-18T20:20:00+00:00', '--job-id', '20', '--raw', '--subdir', 'DAGS_FOLDER/ferry_pipeline_dag.py', '--cfg-path', '/tmp/tmpvdzuupz_']
[2025-07-18T20:25:13.424+0000] {logging_mixin.py:188} WARNING - /home/***/.local/lib/python3.12/site-packages/***/task/task_runner/standard_task_runner.py:61 DeprecationWarning: This process (pid=348) is multi-threaded, use of fork() may lead to deadlocks in the child.
[2025-07-18T20:25:13.426+0000] {standard_task_runner.py:91} INFO - Job 20: Subtask transform_data
[2025-07-18T20:25:13.426+0000] {standard_task_runner.py:63} INFO - Started process 353 to run task
[2025-07-18T20:25:13.451+0000] {logging_mixin.py:188} WARNING - /home/***/.local/lib/python3.12/site-packages/***/settings.py:195 DeprecationWarning: The sql_alchemy_conn option in [core] has been moved to the sql_alchemy_conn option in [database] - the old setting has been used, but please update your config.
[2025-07-18T20:25:13.525+0000] {task_command.py:426} INFO - Running <TaskInstance: ferry_portfolio_etl.transform_data scheduled__2025-07-18T20:20:00+00:00 [running]> on host 41c60911f097
[2025-07-18T20:25:13.630+0000] {taskinstance.py:2648} INFO - Exporting env vars: AIRFLOW_CTX_DAG_OWNER='ashok' AIRFLOW_CTX_DAG_ID='ferry_portfolio_etl' AIRFLOW_CTX_TASK_ID='transform_data' AIRFLOW_CTX_EXECUTION_DATE='2025-07-18T20:20:00+00:00' AIRFLOW_CTX_TRY_NUMBER='1' AIRFLOW_CTX_DAG_RUN_ID='scheduled__2025-07-18T20:20:00+00:00'
[2025-07-18T20:25:13.631+0000] {taskinstance.py:430} INFO - ::endgroup::
[2025-07-18T20:25:13.644+0000] {transform_data.py:22} INFO - ⬇️ Reading file from S3: s3://ashok-ferry-data-bucket/raw_data/raw.csv
[2025-07-18T20:25:13.797+0000] {transform_data.py:30} ERROR - ❌ Error reading from S3: Unable to locate credentials
[2025-07-18T20:25:13.798+0000] {taskinstance.py:441} INFO - ::group::Post task execution logs
[2025-07-18T20:25:13.802+0000] {taskinstance.py:2905} ERROR - Task failed with exception
Traceback (most recent call last):
  File "/opt/airflow/src/ferry_portfolio_pipeline/scripts/transform_data.py", line 24, in read_csv_from_s3
    obj = s3.get_object(Bucket=bucket, Key=key)
          ^^^^^^^^^^^^^^^^^^^^^^^^^^^^^^^^^^^^^
  File "/home/airflow/.local/lib/python3.12/site-packages/botocore/client.py", line 553, in _api_call
    return self._make_api_call(operation_name, kwargs)
           ^^^^^^^^^^^^^^^^^^^^^^^^^^^^^^^^^^^^^^^^^^^
  File "/home/airflow/.local/lib/python3.12/site-packages/botocore/client.py", line 989, in _make_api_call
    http, parsed_response = self._make_request(
                            ^^^^^^^^^^^^^^^^^^^
  File "/home/airflow/.local/lib/python3.12/site-packages/botocore/client.py", line 1015, in _make_request
    return self._endpoint.make_request(operation_model, request_dict)
           ^^^^^^^^^^^^^^^^^^^^^^^^^^^^^^^^^^^^^^^^^^^^^^^^^^^^^^^^^^
  File "/home/airflow/.local/lib/python3.12/site-packages/botocore/endpoint.py", line 119, in make_request
    return self._send_request(request_dict, operation_model)
           ^^^^^^^^^^^^^^^^^^^^^^^^^^^^^^^^^^^^^^^^^^^^^^^^^
  File "/home/airflow/.local/lib/python3.12/site-packages/botocore/endpoint.py", line 198, in _send_request
    request = self.create_request(request_dict, operation_model)
              ^^^^^^^^^^^^^^^^^^^^^^^^^^^^^^^^^^^^^^^^^^^^^^^^^^
  File "/home/airflow/.local/lib/python3.12/site-packages/botocore/endpoint.py", line 134, in create_request
    self._event_emitter.emit(
  File "/home/airflow/.local/lib/python3.12/site-packages/botocore/hooks.py", line 412, in emit
    return self._emitter.emit(aliased_event_name, **kwargs)
           ^^^^^^^^^^^^^^^^^^^^^^^^^^^^^^^^^^^^^^^^^^^^^^^^
  File "/home/airflow/.local/lib/python3.12/site-packages/botocore/hooks.py", line 256, in emit
    return self._emit(event_name, kwargs)
           ^^^^^^^^^^^^^^^^^^^^^^^^^^^^^^
  File "/home/airflow/.local/lib/python3.12/site-packages/botocore/hooks.py", line 239, in _emit
    response = handler(**kwargs)
               ^^^^^^^^^^^^^^^^^
  File "/home/airflow/.local/lib/python3.12/site-packages/botocore/signers.py", line 105, in handler
    return self.sign(operation_name, request)
           ^^^^^^^^^^^^^^^^^^^^^^^^^^^^^^^^^^
  File "/home/airflow/.local/lib/python3.12/site-packages/botocore/signers.py", line 195, in sign
    auth.add_auth(request)
  File "/home/airflow/.local/lib/python3.12/site-packages/botocore/auth.py", line 418, in add_auth
    raise NoCredentialsError()
botocore.exceptions.NoCredentialsError: Unable to locate credentials

During handling of the above exception, another exception occurred:

Traceback (most recent call last):
  File "/home/airflow/.local/lib/python3.12/site-packages/airflow/models/taskinstance.py", line 465, in _execute_task
    result = _execute_callable(context=context, **execute_callable_kwargs)
             ^^^^^^^^^^^^^^^^^^^^^^^^^^^^^^^^^^^^^^^^^^^^^^^^^^^^^^^^^^^^^
  File "/home/airflow/.local/lib/python3.12/site-packages/airflow/models/taskinstance.py", line 432, in _execute_callable
    return execute_callable(context=context, **execute_callable_kwargs)
           ^^^^^^^^^^^^^^^^^^^^^^^^^^^^^^^^^^^^^^^^^^^^^^^^^^^^^^^^^^^^
  File "/home/airflow/.local/lib/python3.12/site-packages/airflow/models/baseoperator.py", line 400, in wrapper
    return func(self, *args, **kwargs)
           ^^^^^^^^^^^^^^^^^^^^^^^^^^^
  File "/home/airflow/.local/lib/python3.12/site-packages/airflow/operators/python.py", line 235, in execute
    return_value = self.execute_callable()
                   ^^^^^^^^^^^^^^^^^^^^^^^
  File "/home/airflow/.local/lib/python3.12/site-packages/airflow/operators/python.py", line 252, in execute_callable
    return self.python_callable(*self.op_args, **self.op_kwargs)
           ^^^^^^^^^^^^^^^^^^^^^^^^^^^^^^^^^^^^^^^^^^^^^^^^^^^^^
  File "/opt/airflow/src/ferry_portfolio_pipeline/scripts/transform_data.py", line 60, in run_transformation
    main()
  File "/opt/airflow/src/ferry_portfolio_pipeline/scripts/transform_data.py", line 70, in main
    df = read_csv_from_s3(bucket, input_key)
         ^^^^^^^^^^^^^^^^^^^^^^^^^^^^^^^^^^^
  File "/opt/airflow/src/ferry_portfolio_pipeline/scripts/transform_data.py", line 31, in read_csv_from_s3
    raise CustomException(e)
          ^^^^^^^^^^^^^^^^^^
TypeError: CustomException.__init__() missing 1 required positional argument: 'error_details'
[2025-07-18T20:25:13.859+0000] {taskinstance.py:1206} INFO - Marking task as UP_FOR_RETRY. dag_id=ferry_portfolio_etl, task_id=transform_data, run_id=scheduled__2025-07-18T20:20:00+00:00, execution_date=20250718T202000, start_date=20250718T202513, end_date=20250718T202513
[2025-07-18T20:25:13.878+0000] {standard_task_runner.py:110} ERROR - Failed to execute job 20 for task transform_data (CustomException.__init__() missing 1 required positional argument: 'error_details'; 353)
[2025-07-18T20:25:13.923+0000] {local_task_job_runner.py:240} INFO - Task exited with return code 1
[2025-07-18T20:25:13.945+0000] {taskinstance.py:3498} INFO - 0 downstream tasks scheduled from follow-on schedule check
[2025-07-18T20:25:13.953+0000] {local_task_job_runner.py:222} INFO - ::endgroup::
