[2025-07-19T17:25:26.918+0000] {local_task_job_runner.py:120} INFO - ::group::Pre task execution logs
[2025-07-19T17:25:26.974+0000] {taskinstance.py:2076} INFO - Dependencies all met for dep_context=non-requeueable deps ti=<TaskInstance: ferry_portfolio_etl.dvc_add_data scheduled__2025-07-19T17:20:00+00:00 [queued]>
[2025-07-19T17:25:26.988+0000] {taskinstance.py:2076} INFO - Dependencies all met for dep_context=requeueable deps ti=<TaskInstance: ferry_portfolio_etl.dvc_add_data scheduled__2025-07-19T17:20:00+00:00 [queued]>
[2025-07-19T17:25:26.989+0000] {taskinstance.py:2306} INFO - Starting attempt 1 of 2
[2025-07-19T17:25:27.007+0000] {taskinstance.py:2330} INFO - Executing <Task(PythonOperator): dvc_add_data> on 2025-07-19 17:20:00+00:00
[2025-07-19T17:25:27.038+0000] {logging_mixin.py:188} WARNING - /home/***/.local/lib/python3.12/site-packages/***/task/task_runner/standard_task_runner.py:61 DeprecationWarning: This process (pid=802) is multi-threaded, use of fork() may lead to deadlocks in the child.
[2025-07-19T17:25:27.032+0000] {standard_task_runner.py:90} INFO - Running: ['***', 'tasks', 'run', 'ferry_portfolio_etl', 'dvc_add_data', 'scheduled__2025-07-19T17:20:00+00:00', '--job-id', '218', '--raw', '--subdir', 'DAGS_FOLDER/ferry_pipeline_dag.py', '--cfg-path', '/tmp/tmp1xmwlz52']
[2025-07-19T17:25:27.043+0000] {standard_task_runner.py:63} INFO - Started process 804 to run task
[2025-07-19T17:25:27.043+0000] {standard_task_runner.py:91} INFO - Job 218: Subtask dvc_add_data
[2025-07-19T17:25:27.074+0000] {logging_mixin.py:188} WARNING - /home/***/.local/lib/python3.12/site-packages/***/settings.py:195 DeprecationWarning: The sql_alchemy_conn option in [core] has been moved to the sql_alchemy_conn option in [database] - the old setting has been used, but please update your config.
[2025-07-19T17:25:27.167+0000] {task_command.py:426} INFO - Running <TaskInstance: ferry_portfolio_etl.dvc_add_data scheduled__2025-07-19T17:20:00+00:00 [running]> on host ee9d4808f134
[2025-07-19T17:25:27.346+0000] {taskinstance.py:2648} INFO - Exporting env vars: AIRFLOW_CTX_DAG_OWNER='ashok' AIRFLOW_CTX_DAG_ID='ferry_portfolio_etl' AIRFLOW_CTX_TASK_ID='dvc_add_data' AIRFLOW_CTX_EXECUTION_DATE='2025-07-19T17:20:00+00:00' AIRFLOW_CTX_TRY_NUMBER='1' AIRFLOW_CTX_DAG_RUN_ID='scheduled__2025-07-19T17:20:00+00:00'
[2025-07-19T17:25:27.349+0000] {taskinstance.py:430} INFO - ::endgroup::
[2025-07-19T17:25:27.380+0000] {logging_mixin.py:188} INFO - File exists? True /opt/***/artifacts/ferry_raw.csv
[2025-07-19T17:25:29.888+0000] {taskinstance.py:441} INFO - ::group::Post task execution logs
[2025-07-19T17:25:29.890+0000] {taskinstance.py:2905} ERROR - Task failed with exception
Traceback (most recent call last):
  File "/home/airflow/.local/lib/python3.12/site-packages/airflow/models/taskinstance.py", line 465, in _execute_task
    result = _execute_callable(context=context, **execute_callable_kwargs)
             ^^^^^^^^^^^^^^^^^^^^^^^^^^^^^^^^^^^^^^^^^^^^^^^^^^^^^^^^^^^^^
  File "/home/airflow/.local/lib/python3.12/site-packages/airflow/models/taskinstance.py", line 432, in _execute_callable
    return execute_callable(context=context, **execute_callable_kwargs)
           ^^^^^^^^^^^^^^^^^^^^^^^^^^^^^^^^^^^^^^^^^^^^^^^^^^^^^^^^^^^^
  File "/home/airflow/.local/lib/python3.12/site-packages/airflow/models/baseoperator.py", line 400, in wrapper
    return func(self, *args, **kwargs)
           ^^^^^^^^^^^^^^^^^^^^^^^^^^^
  File "/home/airflow/.local/lib/python3.12/site-packages/airflow/operators/python.py", line 235, in execute
    return_value = self.execute_callable()
                   ^^^^^^^^^^^^^^^^^^^^^^^
  File "/home/airflow/.local/lib/python3.12/site-packages/airflow/operators/python.py", line 252, in execute_callable
    return self.python_callable(*self.op_args, **self.op_kwargs)
           ^^^^^^^^^^^^^^^^^^^^^^^^^^^^^^^^^^^^^^^^^^^^^^^^^^^^^
  File "/opt/airflow/dags/ferry_pipeline_dag.py", line 51, in run_dvc_add
    subprocess.run(["dvc", "add", data_path], check=True)
  File "/usr/local/lib/python3.12/subprocess.py", line 571, in run
    raise CalledProcessError(retcode, process.args,
subprocess.CalledProcessError: Command '['dvc', 'add', '/opt/airflow/artifacts/ferry_raw.csv']' returned non-zero exit status 253.
[2025-07-19T17:25:29.921+0000] {taskinstance.py:1206} INFO - Marking task as UP_FOR_RETRY. dag_id=ferry_portfolio_etl, task_id=dvc_add_data, run_id=scheduled__2025-07-19T17:20:00+00:00, execution_date=20250719T172000, start_date=20250719T172526, end_date=20250719T172529
[2025-07-19T17:25:29.943+0000] {standard_task_runner.py:110} ERROR - Failed to execute job 218 for task dvc_add_data (Command '['dvc', 'add', '/opt/airflow/artifacts/ferry_raw.csv']' returned non-zero exit status 253.; 804)
[2025-07-19T17:25:29.995+0000] {local_task_job_runner.py:240} INFO - Task exited with return code 1
[2025-07-19T17:25:30.016+0000] {local_task_job_runner.py:222} INFO - ::endgroup::
